Traceback (most recent call last):
  File "<string>", line 1, in <module>
  File "/usr/lib/python2.7/pkgutil.py", line 462, in get_loader
    return find_loader(fullname)
  File "/usr/lib/python2.7/pkgutil.py", line 472, in find_loader
    for importer in iter_importers(fullname):
  File "/usr/lib/python2.7/pkgutil.py", line 428, in iter_importers
    __import__(pkg)
ImportError: No module named mindspore._extends.remote
[ERROR] DEVICE(20798,python3.7):2020-11-27-21:37:33.326.107 [mindspore/ccsrc/backend/session/kernel_build_client.h:154] GetScriptFilePath] py file seems incorrect, result: {}
Traceback (most recent call last):
  File "train.py", line 191, in <module>
    sink_size=dataset.get_dataset_size(), dataset_sink_mode=(not args_opt.parameter_server))
  File "/home/lg/.local/lib/python3.7/site-packages/mindspore/train/model.py", line 565, in train
    sink_size=sink_size)
  File "/home/lg/.local/lib/python3.7/site-packages/mindspore/train/model.py", line 374, in _train
    self._train_dataset_sink_process(epoch, train_dataset, list_callback, cb_params, sink_size)
  File "/home/lg/.local/lib/python3.7/site-packages/mindspore/train/model.py", line 431, in _train_dataset_sink_process
    outputs = self._train_network(*inputs)
  File "/home/lg/.local/lib/python3.7/site-packages/mindspore/nn/cell.py", line 280, in __call__
    out = self.compile_and_run(*inputs)
  File "/home/lg/.local/lib/python3.7/site-packages/mindspore/nn/cell.py", line 535, in compile_and_run
    self.compile(*inputs)
  File "/home/lg/.local/lib/python3.7/site-packages/mindspore/nn/cell.py", line 522, in compile
    _executor.compile(self, *inputs, phase=self.phase, auto_parallel_mode=self._auto_parallel_mode)
  File "/home/lg/.local/lib/python3.7/site-packages/mindspore/common/api.py", line 412, in compile
    result = self._executor.compile(obj, args_list, phase, use_vm)
RuntimeError: mindspore/ccsrc/backend/session/kernel_build_client.h:154 GetScriptFilePath] py file seems incorrect, result: {}
